{
 "cells": [
  {
   "cell_type": "code",
   "execution_count": null,
   "metadata": {},
   "outputs": [],
   "source": [
    "## TensorFlow 1 example"
   ]
  },
  {
   "cell_type": "code",
   "execution_count": null,
   "metadata": {},
   "outputs": [],
   "source": [
    "import numpy as np\n",
    "import tensorflow as tf\n",
    "\n",
    "tf.reset_default_graph()\n",
    "\n",
    "x = tf.placeholder(shape=[1,4],dtype=tf.float32)\n",
    "w1 = tf.Variable(tf.initializers.truncated_normal()(shape=[4,3]), dtype=tf.float32)\n",
    "b1 = tf.Variable(tf.initializers.truncated_normal()(shape=[1,3]), dtype=tf.float32)\n",
    "w2 = tf.Variable(tf.initializers.truncated_normal()(shape=[3,2]), dtype=tf.float32)\n",
    "b2 = tf.Variable(tf.initializers.truncated_normal()(shape=[1,2]), dtype=tf.float32)\n",
    "\n",
    "h = tf.matmul(x, w1) + b1\n",
    "h = tf.nn.sigmoid(h)\n",
    "y = tf.matmul(h, w2) + b2\n",
    "y = tf.nn.softmax(y)\n",
    "\n",
    "\n",
    "with tf.Session() as sess:\n",
    "  sess.run(tf.global_variables_initializer())\n",
    "  res = sess.run(y, feed_dict={x: np.random.normal(size=[1,4])})\n",
    "  print(res)"
   ]
  },
  {
   "cell_type": "code",
   "execution_count": null,
   "metadata": {},
   "outputs": [],
   "source": [
    "## TensorFlow 2 example"
   ]
  },
  {
   "cell_type": "code",
   "execution_count": 5,
   "metadata": {},
   "outputs": [
    {
     "name": "stderr",
     "output_type": "stream",
     "text": [
      "ERROR:root:Internal Python error in the inspect module.\n",
      "Below is the traceback from this internal error.\n",
      "\n"
     ]
    },
    {
     "name": "stdout",
     "output_type": "stream",
     "text": [
      "Traceback (most recent call last):\n",
      "  File \"c:\\anaconda3\\envs\\manning.tf2\\lib\\site-packages\\IPython\\core\\interactiveshell.py\", line 3331, in run_code\n",
      "    exec(code_obj, self.user_global_ns, self.user_ns)\n",
      "  File \"<ipython-input-5-34ae2d14321b>\", line 3, in <module>\n",
      "    print(tf.__version__)\n",
      "AttributeError: module 'tensorflow' has no attribute '__version__'\n",
      "\n",
      "During handling of the above exception, another exception occurred:\n",
      "\n",
      "Traceback (most recent call last):\n",
      "  File \"c:\\anaconda3\\envs\\manning.tf2\\lib\\site-packages\\IPython\\core\\interactiveshell.py\", line 2044, in showtraceback\n",
      "    stb = value._render_traceback_()\n",
      "AttributeError: 'AttributeError' object has no attribute '_render_traceback_'\n",
      "\n",
      "During handling of the above exception, another exception occurred:\n",
      "\n",
      "Traceback (most recent call last):\n",
      "  File \"c:\\anaconda3\\envs\\manning.tf2\\lib\\site-packages\\tensorflow_core\\python\\pywrap_tensorflow.py\", line 58, in <module>\n",
      "    from tensorflow.python.pywrap_tensorflow_internal import *\n",
      "  File \"c:\\anaconda3\\envs\\manning.tf2\\lib\\site-packages\\tensorflow_core\\python\\pywrap_tensorflow_internal.py\", line 28, in <module>\n",
      "    _pywrap_tensorflow_internal = swig_import_helper()\n",
      "  File \"c:\\anaconda3\\envs\\manning.tf2\\lib\\site-packages\\tensorflow_core\\python\\pywrap_tensorflow_internal.py\", line 24, in swig_import_helper\n",
      "    _mod = imp.load_module('_pywrap_tensorflow_internal', fp, pathname, description)\n",
      "  File \"c:\\anaconda3\\envs\\manning.tf2\\lib\\imp.py\", line 243, in load_module\n",
      "    return load_dynamic(name, filename, file)\n",
      "  File \"c:\\anaconda3\\envs\\manning.tf2\\lib\\imp.py\", line 343, in load_dynamic\n",
      "    return _load(spec)\n",
      "ImportError: DLL load failed: The specified module could not be found.\n",
      "\n",
      "During handling of the above exception, another exception occurred:\n",
      "\n",
      "Traceback (most recent call last):\n",
      "  File \"c:\\anaconda3\\envs\\manning.tf2\\lib\\site-packages\\IPython\\core\\ultratb.py\", line 1148, in get_records\n",
      "    return _fixed_getinnerframes(etb, number_of_lines_of_context, tb_offset)\n",
      "  File \"c:\\anaconda3\\envs\\manning.tf2\\lib\\site-packages\\IPython\\core\\ultratb.py\", line 316, in wrapped\n",
      "    return f(*args, **kwargs)\n",
      "  File \"c:\\anaconda3\\envs\\manning.tf2\\lib\\site-packages\\IPython\\core\\ultratb.py\", line 350, in _fixed_getinnerframes\n",
      "    records = fix_frame_records_filenames(inspect.getinnerframes(etb, context))\n",
      "  File \"c:\\anaconda3\\envs\\manning.tf2\\lib\\inspect.py\", line 1490, in getinnerframes\n",
      "    frameinfo = (tb.tb_frame,) + getframeinfo(tb, context)\n",
      "  File \"c:\\anaconda3\\envs\\manning.tf2\\lib\\inspect.py\", line 1448, in getframeinfo\n",
      "    filename = getsourcefile(frame) or getfile(frame)\n",
      "  File \"c:\\anaconda3\\envs\\manning.tf2\\lib\\inspect.py\", line 696, in getsourcefile\n",
      "    if getattr(getmodule(object, filename), '__loader__', None) is not None:\n",
      "  File \"c:\\anaconda3\\envs\\manning.tf2\\lib\\inspect.py\", line 733, in getmodule\n",
      "    if ismodule(module) and hasattr(module, '__file__'):\n",
      "  File \"c:\\anaconda3\\envs\\manning.tf2\\lib\\site-packages\\tensorflow\\__init__.py\", line 50, in __getattr__\n",
      "    module = self._load()\n",
      "  File \"c:\\anaconda3\\envs\\manning.tf2\\lib\\site-packages\\tensorflow\\__init__.py\", line 44, in _load\n",
      "    module = _importlib.import_module(self.__name__)\n",
      "  File \"c:\\anaconda3\\envs\\manning.tf2\\lib\\importlib\\__init__.py\", line 126, in import_module\n",
      "    return _bootstrap._gcd_import(name[level:], package, level)\n",
      "  File \"<frozen importlib._bootstrap>\", line 994, in _gcd_import\n",
      "  File \"<frozen importlib._bootstrap>\", line 971, in _find_and_load\n",
      "  File \"<frozen importlib._bootstrap>\", line 941, in _find_and_load_unlocked\n",
      "  File \"<frozen importlib._bootstrap>\", line 219, in _call_with_frames_removed\n",
      "  File \"<frozen importlib._bootstrap>\", line 994, in _gcd_import\n",
      "  File \"<frozen importlib._bootstrap>\", line 971, in _find_and_load\n",
      "  File \"<frozen importlib._bootstrap>\", line 955, in _find_and_load_unlocked\n",
      "  File \"<frozen importlib._bootstrap>\", line 665, in _load_unlocked\n",
      "  File \"<frozen importlib._bootstrap_external>\", line 678, in exec_module\n",
      "  File \"<frozen importlib._bootstrap>\", line 219, in _call_with_frames_removed\n",
      "  File \"c:\\anaconda3\\envs\\manning.tf2\\lib\\site-packages\\tensorflow_core\\__init__.py\", line 42, in <module>\n",
      "    from . _api.v2 import audio\n",
      "  File \"c:\\anaconda3\\envs\\manning.tf2\\lib\\site-packages\\tensorflow_core\\_api\\v2\\audio\\__init__.py\", line 10, in <module>\n",
      "    from tensorflow.python.ops.gen_audio_ops import decode_wav\n",
      "  File \"c:\\anaconda3\\envs\\manning.tf2\\lib\\site-packages\\tensorflow_core\\python\\ops\\gen_audio_ops.py\", line 9, in <module>\n",
      "    from tensorflow.python import pywrap_tensorflow as _pywrap_tensorflow\n",
      "  File \"c:\\anaconda3\\envs\\manning.tf2\\lib\\site-packages\\tensorflow\\__init__.py\", line 50, in __getattr__\n",
      "    module = self._load()\n",
      "  File \"c:\\anaconda3\\envs\\manning.tf2\\lib\\site-packages\\tensorflow\\__init__.py\", line 44, in _load\n",
      "    module = _importlib.import_module(self.__name__)\n",
      "  File \"c:\\anaconda3\\envs\\manning.tf2\\lib\\importlib\\__init__.py\", line 126, in import_module\n",
      "    return _bootstrap._gcd_import(name[level:], package, level)\n",
      "  File \"c:\\anaconda3\\envs\\manning.tf2\\lib\\site-packages\\tensorflow_core\\python\\__init__.py\", line 49, in <module>\n",
      "    from tensorflow.python import pywrap_tensorflow\n",
      "  File \"c:\\anaconda3\\envs\\manning.tf2\\lib\\site-packages\\tensorflow_core\\python\\pywrap_tensorflow.py\", line 74, in <module>\n",
      "    raise ImportError(msg)\n",
      "ImportError: Traceback (most recent call last):\n",
      "  File \"c:\\anaconda3\\envs\\manning.tf2\\lib\\site-packages\\IPython\\core\\interactiveshell.py\", line 3331, in run_code\n",
      "    exec(code_obj, self.user_global_ns, self.user_ns)\n",
      "  File \"<ipython-input-5-34ae2d14321b>\", line 3, in <module>\n",
      "    print(tf.__version__)\n",
      "AttributeError: module 'tensorflow' has no attribute '__version__'\n",
      "\n",
      "During handling of the above exception, another exception occurred:\n",
      "\n",
      "Traceback (most recent call last):\n",
      "  File \"c:\\anaconda3\\envs\\manning.tf2\\lib\\site-packages\\IPython\\core\\interactiveshell.py\", line 2044, in showtraceback\n",
      "    stb = value._render_traceback_()\n",
      "AttributeError: 'AttributeError' object has no attribute '_render_traceback_'\n",
      "\n",
      "During handling of the above exception, another exception occurred:\n",
      "\n",
      "Traceback (most recent call last):\n",
      "  File \"c:\\anaconda3\\envs\\manning.tf2\\lib\\site-packages\\tensorflow_core\\python\\pywrap_tensorflow.py\", line 58, in <module>\n",
      "    from tensorflow.python.pywrap_tensorflow_internal import *\n",
      "  File \"c:\\anaconda3\\envs\\manning.tf2\\lib\\site-packages\\tensorflow_core\\python\\pywrap_tensorflow_internal.py\", line 28, in <module>\n",
      "    _pywrap_tensorflow_internal = swig_import_helper()\n",
      "  File \"c:\\anaconda3\\envs\\manning.tf2\\lib\\site-packages\\tensorflow_core\\python\\pywrap_tensorflow_internal.py\", line 24, in swig_import_helper\n",
      "    _mod = imp.load_module('_pywrap_tensorflow_internal', fp, pathname, description)\n",
      "  File \"c:\\anaconda3\\envs\\manning.tf2\\lib\\imp.py\", line 243, in load_module\n",
      "    return load_dynamic(name, filename, file)\n",
      "  File \"c:\\anaconda3\\envs\\manning.tf2\\lib\\imp.py\", line 343, in load_dynamic\n",
      "    return _load(spec)\n",
      "ImportError: DLL load failed: The specified module could not be found.\n",
      "\n",
      "\n",
      "Failed to load the native TensorFlow runtime.\n",
      "\n",
      "See https://www.tensorflow.org/install/errors\n",
      "\n",
      "for some common reasons and solutions.  Include the entire stack trace\n",
      "above this error message when asking for help.\n"
     ]
    },
    {
     "ename": "AttributeError",
     "evalue": "module 'tensorflow' has no attribute '__version__'",
     "output_type": "error",
     "traceback": [
      "\u001b[1;31m---------------------------------------------------------------------------\u001b[0m"
     ]
    }
   ],
   "source": [
    "import numpy as np\n",
    "import tensorflow as tf\n",
    "print(tf.__version__)\n",
    "@tf.function\n",
    "def forward(x, W, b, act):\n",
    "    return act(tf.matmul(x,W)+b)\n",
    "\n",
    "\n",
    "x = np.random.normal(size=[1,4])\n",
    "init = tf.keras.initializers.truncated_normal()\n",
    "w1 = tf.Variable(init(shape=[4,3]))\n",
    "b1 = tf.Variable(init(shape=[1,3]))\n",
    "w2 = tf.Variable(init(shape=[3,2]))\n",
    "b2 = tf.Variable(init(shape=[1,2]))\n",
    "\n",
    "h = forward(x, w1, b1, tf.nn.sigmoid)\n",
    "y = forward(h, w2, b2, tf.nn.softmax)\n",
    "\n",
    "print(res)\n",
    "    "
   ]
  },
  {
   "cell_type": "code",
   "execution_count": null,
   "metadata": {},
   "outputs": [],
   "source": []
  }
 ],
 "metadata": {
  "kernelspec": {
   "display_name": "Python 3",
   "language": "python",
   "name": "python3"
  },
  "language_info": {
   "codemirror_mode": {
    "name": "ipython",
    "version": 3
   },
   "file_extension": ".py",
   "mimetype": "text/x-python",
   "name": "python",
   "nbconvert_exporter": "python",
   "pygments_lexer": "ipython3",
   "version": "3.6.10"
  }
 },
 "nbformat": 4,
 "nbformat_minor": 4
}
